Workbook

Sheet Gantt
A2: AuroraCare - Carta Gantt
A4: Corte al 23/10/2026. Calendario semanal del 31/08 al 20/12/2026.
A6: Verde: avance por subtareas. Color de fase: plan pendiente. Jira / Mixto / Sprint: origen de fechas.
A7: Inicio/fin reales no verificados. Avance por conteo, no por esfuerzo. PDF: corte estático de esta versión.
A9: Clave | B9: Actividad principal | C9: Responsable | D9: Inicio plan | E9: Término plan | F9: Origen fechas | G9: Estado Jira | H9: Subtareas | I9: Terminadas | J9: Avance | K9: Días calendario | L9: Dependencias (validar) | M9: 46265 | N9: 46272 | O9: 46279 | P9: 46286 | Q9: 46293 | R9: 46300 | S9: 46307 | T9: 46314 | U9: 46321 | V9: 46328 | W9: 46335 | X9: 46342 | Y9: 46349 | Z9: 46356 | AA9: 46363 | AB9: 46370
B10: Fundamentos
A11: SCRUM-5 | B11: Instalar stack en los equipos de desarrollo | C11: Daniela | D11: =IF('Datos Jira'!G8="",'Datos Jira'!J8,'Datos Jira'!G8) -> 46265 | E11: =IF('Datos Jira'!H8="",'Datos Jira'!K8,'Datos Jira'!H8) -> 46270 | F11: Jira | G11: ='Datos Jira'!E8 -> Finalizado | H11: =COUNTIFS('Datos Jira'!$B$8:$B$234,A11) -> 3 | I11: =COUNTIFS('Datos Jira'!$B$8:$B$234,A11,'Datos Jira'!$E$8:$E$234,"Finalizado") -> 3 | J11: =IF(G11="Finalizado",1,IF(H11>0,I11/H11,IF(G11="Pendiente",0,""))) -> 1 | K11: =E11-D11+1 -> 6 | M11: =IF(AND($D11<=M$9+6,$E11>=M$9),IF(AND(ISNUMBER($J11),M$9<=$D11+($E11-$D11+1)*$J11-1),2,1),0) -> 2 | N11: =IF(AND($D11<=N$9+6,$E11>=N$9),IF(AND(ISNUMBER($J11),N$9<=$D11+($E11-$D11+1)*$J11-1),2,1),0) -> 0 | O11: =IF(AND($D11<=O$9+6,$E11>=O$9),IF(AND(ISNUMBER($J11),O$9<=$D11+($E11-$D11+1)*$J11-1),2,1),0) -> 0 | P11: =IF(AND($D11<=P$9+6,$E11>=P$9),IF(AND(ISNUMBER($J11),P$9<=$D11+($E11-$D11+1)*$J11-1),2,1),0) -> 0 | Q11: =IF(AND($D11<=Q$9+6,$E11>=Q$9),IF(AND(ISNUMBER($J11),Q$9<=$D11+($E11-$D11+1)*$J11-1),2,1),0) -> 0 | R11: =IF(AND($D11<=R$9+6,$E11>=R$9),IF(AND(ISNUMBER($J11),R$9<=$D11+($E11-$D11+1)*$J11-1),2,1),0) -> 0 | S11: =IF(AND($D11<=S$9+6,$E11>=S$9),IF(AND(ISNUMBER($J11),S$9<=$D11+($E11-$D11+1)*$J11-1),2,1),0) -> 0 | T11: =IF(AND($D11<=T$9+6,$E11>=T$9),IF(AND(ISNUMBER($J11),T$9<=$D11+($E11-$D11+1)*$J11-1),2,1),0) -> 0 | ... AB11: =IF(AND($D11<=AB$9+6,$E11>=AB$9),IF(AND(ISNUMBER($J11),AB$9<=$D11+($E11-$D11+1)*$J11-1),2,1),0) -> 0
A12: SCRUM-6 | B12: Configurar repositorio GitHub | C12: Daniela | D12: =IF('Datos Jira'!G9="",'Datos Jira'!J9,'Datos Jira'!G9) -> 46265 | E12: =IF('Datos Jira'!H9="",'Datos Jira'!K9,'Datos Jira'!H9) -> 46278 | F12: Mixto | G12: ='Datos Jira'!E9 -> Finalizado | H12: =COUNTIFS('Datos Jira'!$B$8:$B$234,A12) -> 4 | I12: =COUNTIFS('Datos Jira'!$B$8:$B$234,A12,'Datos Jira'!$E$8:$E$234,"Finalizado") -> 4 | J12: =IF(G12="Finalizado",1,IF(H12>0,I12/H12,IF(G12="Pendiente",0,""))) -> 1 | K12: =E12-D12+1 -> 14 | M12: =IF(AND($D12<=M$9+6,$E12>=M$9),IF(AND(ISNUMBER($J12),M$9<=$D12+($E12-$D12+1)*$J12-1),2,1),0) -> 2 | N12: =IF(AND($D12<=N$9+6,$E12>=N$9),IF(AND(ISNUMBER($J12),N$9<=$D12+($E12-$D12+1)*$J12-1),2,1),0) -> 2 | O12: =IF(AND($D12<=O$9+6,$E12>=O$9),IF(AND(ISNUMBER($J12),O$9<=$D12+($E12-$D12+1)*$J12-1),2,1),0) -> 0 | P12: =IF(AND($D12<=P$9+6,$E12>=P$9),IF(AND(ISNUMBER($J12),P$9<=$D12+($E12-$D12+1)*$J12-1),2,1),0) -> 0 | Q12: =IF(AND($D12<=Q$9+6,$E12>=Q$9),IF(AND(ISNUMBER($J12),Q$9<=$D12+($E12-$D12+1)*$J12-1),2,1),0) -> 0 | R12: =IF(AND($D12<=R$9+6,$E12>=R$9),IF(AND(ISNUMBER($J12),R$9<=$D12+($E12-$D12+1)*$J12-1),2,1),0) -> 0 | S12: =IF(AND($D12<=S$9+6,$E12>=S$9),IF(AND(ISNUMBER($J12),S$9<=$D12+($E12-$D12+1)*$J12-1),2,1),0) -> 0 | T12: =IF(AND($D12<=T$9+6,$E12>=T$9),IF(AND(ISNUMBER($J12),T$9<=$D12+($E12-$D12+1)*$J12-1),2,1),0) -> 0 | ... AB12: =IF(AND($D12<=AB$9+6,$E12>=AB$9),IF(AND(ISNUMBER($J12),AB$9<=$D12+($E12-$D12+1)*$J12-1),2,1),0) -> 0
A13: SCRUM-7 | B13: Crear proyecto Firebase | C13: Daniela | D13: =IF('Datos Jira'!G10="",'Datos Jira'!J10,'Datos Jira'!G10) -> 46265 | E13: =IF('Datos Jira'!H10="",'Datos Jira'!K10,'Datos Jira'!H10) -> 46278 | F13: Mixto | G13: ='Datos Jira'!E10 -> Finalizado | H13: =COUNTIFS('Datos Jira'!$B$8:$B$234,A13) -> 6 | I13: =COUNTIFS('Datos Jira'!$B$8:$B$234,A13,'Datos Jira'!$E$8:$E$234,"Finalizado") -> 6 | J13: =IF(G13="Finalizado",1,IF(H13>0,I13/H13,IF(G13="Pendiente",0,""))) -> 1 | K13: =E13-D13+1 -> 14 | M13: =IF(AND($D13<=M$9+6,$E13>=M$9),IF(AND(ISNUMBER($J13),M$9<=$D13+($E13-$D13+1)*$J13-1),2,1),0) -> 2 | N13: =IF(AND($D13<=N$9+6,$E13>=N$9),IF(AND(ISNUMBER($J13),N$9<=$D13+($E13-$D13+1)*$J13-1),2,1),0) -> 2 | O13: =IF(AND($D13<=O$9+6,$E13>=O$9),IF(AND(ISNUMBER($J13),O$9<=$D13+($E13-$D13+1)*$J13-1),2,1),0) -> 0 | P13: =IF(AND($D13<=P$9+6,$E13>=P$9),IF(AND(ISNUMBER($J13),P$9<=$D13+($E13-$D13+1)*$J13-1),2,1),0) -> 0 | Q13: =IF(AND($D13<=Q$9+6,$E13>=Q$9),IF(AND(ISNUMBER($J13),Q$9<=$D13+($E13-$D13+1)*$J13-1),2,1),0) -> 0 | R13: =IF(AND($D13<=R$9+6,$E13>=R$9),IF(AND(ISNUMBER($J13),R$9<=$D13+($E13-$D13+1)*$J13-1),2,1),0) -> 0 | S13: =IF(AND($D13<=S$9+6,$E13>=S$9),IF(AND(ISNUMBER($J13),S$9<=$D13+($E13-$D13+1)*$J13-1),2,1),0) -> 0 | T13: =IF(AND($D13<=T$9+6,$E13>=T$9),IF(AND(ISNUMBER($J13),T$9<=$D13+($E13-$D13+1)*$J13-1),2,1),0) -> 0 | ... AB13: =IF(AND($D13<=AB$9+6,$E13>=AB$9),IF(AND(ISNUMBER($J13),AB$9<=$D13+($E13-$D13+1)*$J13-1),2,1),0) -> 0
A14: SCRUM-8 | B14: Spike técnico Flutter -> FastAPI -> OpenAI | C14: Daniela | D14: =IF('Datos Jira'!G11="",'Datos Jira'!J11,'Datos Jira'!G11) -> 46267 | E14: =IF('Datos Jira'!H11="",'Datos Jira'!K11,'Datos Jira'!H11) -> 46278 | F14: Jira | G14: ='Datos Jira'!E11 -> Finalizado | H14: =COUNTIFS('Datos Jira'!$B$8:$B$234,A14) -> 6 | I14: =COUNTIFS('Datos Jira'!$B$8:$B$234,A14,'Datos Jira'!$E$8:$E$234,"Finalizado") -> 6 | J14: =IF(G14="Finalizado",1,IF(H14>0,I14/H14,IF(G14="Pendiente",0,""))) -> 1 | K14: =E14-D14+1 -> 12 | M14: =IF(AND($D14<=M$9+6,$E14>=M$9),IF(AND(ISNUMBER($J14),M$9<=$D14+($E14-$D14+1)*$J14-1),2,1),0) -> 2 | N14: =IF(AND($D14<=N$9+6,$E14>=N$9),IF(AND(ISNUMBER($J14),N$9<=$D14+($E14-$D14+1)*$J14-1),2,1),0) -> 2 | O14: =IF(AND($D14<=O$9+6,$E14>=O$9),IF(AND(ISNUMBER($J14),O$9<=$D14+($E14-$D14+1)*$J14-1),2,1),0) -> 0 | P14: =IF(AND($D14<=P$9+6,$E14>=P$9),IF(AND(ISNUMBER($J14),P$9<=$D14+($E14-$D14+1)*$J14-1),2,1),0) -> 0 | Q14: =IF(AND($D14<=Q$9+6,$E14>=Q$9),IF(AND(ISNUMBER($J14),Q$9<=$D14+($E14-$D14+1)*$J14-1),2,1),0) -> 0 | R14: =IF(AND($D14<=R$9+6,$E14>=R$9),IF(AND(ISNUMBER($J14),R$9<=$D14+($E14-$D14+1)*$J14-1),2,1),0) -> 0 | S14: =IF(AND($D14<=S$9+6,$E14>=S$9),IF(AND(ISNUMBER($J14),S$9<=$D14+($E14-$D14+1)*$J14-1),2,1),0) -> 0 | T14: =IF(AND($D14<=T$9+6,$E14>=T$9),IF(AND(ISNUMBER($J14),T$9<=$D14+($E14-$D14+1)*$J14-1),2,1),0) -> 0 | ... AB14: =IF(AND($D14<=AB$9+6,$E14>=AB$9),IF(AND(ISNUMBER($J14),AB$9<=$D14+($E14-$D14+1)*$J14-1),2,1),0) -> 0
A15: SCRUM-9 | B15: Configurar Jira | C15: Daniela | D15: =IF('Datos Jira'!G12="",'Datos Jira'!J12,'Datos Jira'!G12) -> 46265 | E15: =IF('Datos Jira'!H12="",'Datos Jira'!K12,'Datos Jira'!H12) -> 46270 | F15: Mixto | G15: ='Datos Jira'!E12 -> Finalizado | H15: =COUNTIFS('Datos Jira'!$B$8:$B$234,A15) -> 5 | I15: =COUNTIFS('Datos Jira'!$B$8:$B$234,A15,'Datos Jira'!$E$8:$E$234,"Finalizado") -> 5 | J15: =IF(G15="Finalizado",1,IF(H15>0,I15/H15,IF(G15="Pendiente",0,""))) -> 1 | K15: =E15-D15+1 -> 6 | M15: =IF(AND($D15<=M$9+6,$E15>=M$9),IF(AND(ISNUMBER($J15),M$9<=$D15+($E15-$D15+1)*$J15-1),2,1),0) -> 2 | N15: =IF(AND($D15<=N$9+6,$E15>=N$9),IF(AND(ISNUMBER($J15),N$9<=$D15+($E15-$D15+1)*$J15-1),2,1),0) -> 0 | O15: =IF(AND($D15<=O$9+6,$E15>=O$9),IF(AND(ISNUMBER($J15),O$9<=$D15+($E15-$D15+1)*$J15-1),2,1),0) -> 0 | P15: =IF(AND($D15<=P$9+6,$E15>=P$9),IF(AND(ISNUMBER($J15),P$9<=$D15+($E15-$D15+1)*$J15-1),2,1),0) -> 0 | Q15: =IF(AND($D15<=Q$9+6,$E15>=Q$9),IF(AND(ISNUMBER($J15),Q$9<=$D15+($E15-$D15+1)*$J15-1),2,1),0) -> 0 | R15: =IF(AND($D15<=R$9+6,$E15>=R$9),IF(AND(ISNUMBER($J15),R$9<=$D15+($E15-$D15+1)*$J15-1),2,1),0) -> 0 | S15: =IF(AND($D15<=S$9+6,$E15>=S$9),IF(AND(ISNUMBER($J15),S$9<=$D15+($E15-$D15+1)*$J15-1),2,1),0) -> 0 | T15: =IF(AND($D15<=T$9+6,$E15>=T$9),IF(AND(ISNUMBER($J15),T$9<=$D15+($E15-$D15+1)*$J15-1),2,1),0) -> 0 | ... AB15: =IF(AND($D15<=AB$9+6,$E15>=AB$9),IF(AND(ISNUMBER($J15),AB$9<=$D15+($E15-$D15+1)*$J15-1),2,1),0) -> 0
A16: SCRUM-10 | B16: Reunión de kickoff del equipo | C16: Daniela | D16: =IF('Datos Jira'!G13="",'Datos Jira'!J13,'Datos Jira'!G13) -> 46265 | E16: =IF('Datos Jira'!H13="",'Datos Jira'!K13,'Datos Jira'!H13) -> 46275 | F16: Mixto | G16: ='Datos Jira'!E13 -> Finalizado | H16: =COUNTIFS('Datos Jira'!$B$8:$B$234,A16) -> 6 | I16: =COUNTIFS('Datos Jira'!$B$8:$B$234,A16,'Datos Jira'!$E$8:$E$234,"Finalizado") -> 6 | J16: =IF(G16="Finalizado",1,IF(H16>0,I16/H16,IF(G16="Pendiente",0,""))) -> 1 | K16: =E16-D16+1 -> 11 | M16: =IF(AND($D16<=M$9+6,$E16>=M$9),IF(AND(ISNUMBER($J16),M$9<=$D16+($E16-$D16+1)*$J16-1),2,1),0) -> 2 | N16: =IF(AND($D16<=N$9+6,$E16>=N$9),IF(AND(ISNUMBER($J16),N$9<=$D16+($E16-$D16+1)*$J16-1),2,1),0) -> 2 | O16: =IF(AND($D16<=O$9+6,$E16>=O$9),IF(AND(ISNUMBER($J16),O$9<=$D16+($E16-$D16+1)*$J16-1),2,1),0) -> 0 | P16: =IF(AND($D16<=P$9+6,$E16>=P$9),IF(AND(ISNUMBER($J16),P$9<=$D16+($E16-$D16+1)*$J16-1),2,1),0) -> 0 | Q16: =IF(AND($D16<=Q$9+6,$E16>=Q$9),IF(AND(ISNUMBER($J16),Q$9<=$D16+($E16-$D16+1)*$J16-1),2,1),0) -> 0 | R16: =IF(AND($D16<=R$9+6,$E16>=R$9),IF(AND(ISNUMBER($J16),R$9<=$D16+($E16-$D16+1)*$J16-1),2,1),0) -> 0 | S16: =IF(AND($D16<=S$9+6,$E16>=S$9),IF(AND(ISNUMBER($J16),S$9<=$D16+($E16-$D16+1)*$J16-1),2,1),0) -> 0 | T16: =IF(AND($D16<=T$9+6,$E16>=T$9),IF(AND(ISNUMBER($J16),T$9<=$D16+($E16-$D16+1)*$J16-1),2,1),0) -> 0 | ... AB16: =IF(AND($D16<=AB$9+6,$E16>=AB$9),IF(AND(ISNUMBER($J16),AB$9<=$D16+($E16-$D16+1)*$J16-1),2,1),0) -> 0
B17: Arquitectura y autenticación
A18: SCRUM-14 | B18: Estructura de capas Flutter | C18: Daniela | D18: =IF('Datos Jira'!G17="",'Datos Jira'!J17,'Datos Jira'!G17) -> 46273 | E18: =IF('Datos Jira'!H17="",'Datos Jira'!K17,'Datos Jira'!H17) -> 46287 | F18: Mixto | G18: ='Datos Jira'!E17 -> Finalizado | H18: =COUNTIFS('Datos Jira'!$B$8:$B$234,A18) -> 8 | I18: =COUNTIFS('Datos Jira'!$B$8:$B$234,A18,'Datos Jira'!$E$8:$E$234,"Finalizado") -> 8 | J18: =IF(G18="Finalizado",1,IF(H18>0,I18/H18,IF(G18="Pendiente",0,""))) -> 1 | K18: =E18-D18+1 -> 15 | M18: =IF(AND($D18<=M$9+6,$E18>=M$9),IF(AND(ISNUMBER($J18),M$9<=$D18+($E18-$D18+1)*$J18-1),2,1),0) -> 0 | N18: =IF(AND($D18<=N$9+6,$E18>=N$9),IF(AND(ISNUMBER($J18),N$9<=$D18+($E18-$D18+1)*$J18-1),2,1),0) -> 2 | O18: =IF(AND($D18<=O$9+6,$E18>=O$9),IF(AND(ISNUMBER($J18),O$9<=$D18+($E18-$D18+1)*$J18-1),2,1),0) -> 2 | P18: =IF(AND($D18<=P$9+6,$E18>=P$9),IF(AND(ISNUMBER($J18),P$9<=$D18+($E18-$D18+1)*$J18-1),2,1),0) -> 2 | Q18: =IF(AND($D18<=Q$9+6,$E18>=Q$9),IF(AND(ISNUMBER($J18),Q$9<=$D18+($E18-$D18+1)*$J18-1),2,1),0) -> 0 | R18: =IF(AND($D18<=R$9+6,$E18>=R$9),IF(AND(ISNUMBER($J18),R$9<=$D18+($E18-$D18+1)*$J18-1),2,1),0) -> 0 | S18: =IF(AND($D18<=S$9+6,$E18>=S$9),IF(AND(ISNUMBER($J18),S$9<=$D18+($E18-$D18+1)*$J18-1),2,1),0) -> 0 | T18: =IF(AND($D18<=T$9+6,$E18>=T$9),IF(AND(ISNUMBER($J18),T$9<=$D18+($E18-$D18+1)*$J18-1),2,1),0) -> 0 | ... AB18: =IF(AND($D18<=AB$9+6,$E18>=AB$9),IF(AND(ISNUMBER($J18),AB$9<=$D18+($E18-$D18+1)*$J18-1),2,1),0) -> 0
A19: SCRUM-15 | B19: Tema visual AuroraCare | C19: Benjamín | D19: =IF('Datos Jira'!G18="",'Datos Jira'!J18,'Datos Jira'!G18) -> 46273 | E19: =IF('Datos Jira'!H18="",'Datos Jira'!K18,'Datos Jira'!H18) -> 46287 | F19: Mixto | G19: ='Datos Jira'!E18 -> Finalizado | H19: =COUNTIFS('Datos Jira'!$B$8:$B$234,A19) -> 0 | I19: =COUNTIFS('Datos Jira'!$B$8:$B$234,A19,'Datos Jira'!$E$8:$E$234,"Finalizado") -> 0 | J19: =IF(G19="Finalizado",1,IF(H19>0,I19/H19,IF(G19="Pendiente",0,""))) -> 1 | K19: =E19-D19+1 -> 15 | M19: =IF(AND($D19<=M$9+6,$E19>=M$9),IF(AND(ISNUMBER($J19),M$9<=$D19+($E19-$D19+1)*$J19-1),2,1),0) -> 0 | N19: =IF(AND($D19<=N$9+6,$E19>=N$9),IF(AND(ISNUMBER($J19),N$9<=$D19+($E19-$D19+1)*$J19-1),2,1),0) -> 2 | O19: =IF(AND($D19<=O$9+6,$E19>=O$9),IF(AND(ISNUMBER($J19),O$9<=$D19+($E19-$D19+1)*$J19-1),2,1),0) -> 2 | P19: =IF(AND($D19<=P$9+6,$E19>=P$9),IF(AND(ISNUMBER($J19),P$9<=$D19+($E19-$D19+1)*$J19-1),2,1),0) -> 2 | Q19: =IF(AND($D19<=Q$9+6,$E19>=Q$9),IF(AND(ISNUMBER($J19),Q$9<=$D19+($E19-$D19+1)*$J19-1),2,1),0) -> 0 | R19: =IF(AND($D19<=R$9+6,$E19>=R$9),IF(AND(ISNUMBER($J19),R$9<=$D19+($E19-$D19+1)*$J19-1),2,1),0) -> 0 | S19: =IF(AND($D19<=S$9+6,$E19>=S$9),IF(AND(ISNUMBER($J19),S$9<=$D19+($E19-$D19+1)*$J19-1),2,1),0) -> 0 | T19: =IF(AND($D19<=T$9+6,$E19>=T$9),IF(AND(ISNUMBER($J19),T$9<=$D19+($E19-$D19+1)*$J19-1),2,1),0) -> 0 | ... AB19: =IF(AND($D19<=AB$9+6,$E19>=AB$9),IF(AND(ISNUMBER($J19),AB$9<=$D19+($E19-$D19+1)*$J19-1),2,1),0) -> 0
A20: SCRUM-16 | B20: Pantalla de Bienvenida y Login | C20: Benjamín | D20: =IF('Datos Jira'!G19="",'Datos Jira'!J19,'Datos Jira'!G19) -> 46273 | E20: =IF('Datos Jira'!H19="",'Datos Jira'!K19,'Datos Jira'!H19) -> 46291 | F20: Mixto | G20: ='Datos Jira'!E19 -> Finalizado | H20: =COUNTIFS('Datos Jira'!$B$8:$B$234,A20) -> 4 | I20: =COUNTIFS('Datos Jira'!$B$8:$B$234,A20,'Datos Jira'!$E$8:$E$234,"Finalizado") -> 4 | J20: =IF(G20="Finalizado",1,IF(H20>0,I20/H20,IF(G20="Pendiente",0,""))) -> 1 | K20: =E20-D20+1 -> 19 | M20: =IF(AND($D20<=M$9+6,$E20>=M$9),IF(AND(ISNUMBER($J20),M$9<=$D20+($E20-$D20+1)*$J20-1),2,1),0) -> 0 | N20: =IF(AND($D20<=N$9+6,$E20>=N$9),IF(AND(ISNUMBER($J20),N$9<=$D20+($E20-$D20+1)*$J20-1),2,1),0) -> 2 | O20: =IF(AND($D20<=O$9+6,$E20>=O$9),IF(AND(ISNUMBER($J20),O$9<=$D20+($E20-$D20+1)*$J20-1),2,1),0) -> 2 | P20: =IF(AND($D20<=P$9+6,$E20>=P$9),IF(AND(ISNUMBER($J20),P$9<=$D20+($E20-$D20+1)*$J20-1),2,1),0) -> 2 | Q20: =IF(AND($D20<=Q$9+6,$E20>=Q$9),IF(AND(ISNUMBER($J20),Q$9<=$D20+($E20-$D20+1)*$J20-1),2,1),0) -> 0 | R20: =IF(AND($D20<=R$9+6,$E20>=R$9),IF(AND(ISNUMBER($J20),R$9<=$D20+($E20-$D20+1)*$J20-1),2,1),0) -> 0 | S20: =IF(AND($D20<=S$9+6,$E20>=S$9),IF(AND(ISNUMBER($J20),S$9<=$D20+($E20-$D20+1)*$J20-1),2,1),0) -> 0 | T20: =IF(AND($D20<=T$9+6,$E20>=T$9),IF(AND(ISNUMBER($J20),T$9<=$D20+($E20-$D20+1)*$J20-1),2,1),0) -> 0 | ... AB20: =IF(AND($D20<=AB$9+6,$E20>=AB$9),IF(AND(ISNUMBER($J20),AB$9<=$D20+($E20-$D20+1)*$J20-1),2,1),0) -> 0
A21: SCRUM-17 | B21: Disclaimer médico en onboarding | C21: Benjamín | D21: =IF('Datos Jira'!G20="",'Datos Jira'!J20,'Datos Jira'!G20) -> 46273 | E21: =IF('Datos Jira'!H20="",'Datos Jira'!K20,'Datos Jira'!H20) -> 46291 | F21: Mixto | G21: ='Datos Jira'!E20 -> Finalizado | H21: =COUNTIFS('Datos Jira'!$B$8:$B$234,A21) -> 4 | I21: =COUNTIFS('Datos Jira'!$B$8:$B$234,A21,'Datos Jira'!$E$8:$E$234,"Finalizado") -> 4 | J21: =IF(G21="Finalizado",1,IF(H21>0,I21/H21,IF(G21="Pendiente",0,""))) -> 1 | K21: =E21-D21+1 -> 19 | M21: =IF(AND($D21<=M$9+6,$E21>=M$9),IF(AND(ISNUMBER($J21),M$9<=$D21+($E21-$D21+1)*$J21-1),2,1),0) -> 0 | N21: =IF(AND($D21<=N$9+6,$E21>=N$9),IF(AND(ISNUMBER($J21),N$9<=$D21+($E21-$D21+1)*$J21-1),2,1),0) -> 2 | O21: =IF(AND($D21<=O$9+6,$E21>=O$9),IF(AND(ISNUMBER($J21),O$9<=$D21+($E21-$D21+1)*$J21-1),2,1),0) -> 2 | P21: =IF(AND($D21<=P$9+6,$E21>=P$9),IF(AND(ISNUMBER($J21),P$9<=$D21+($E21-$D21+1)*$J21-1),2,1),0) -> 2 | Q21: =IF(AND($D21<=Q$9+6,$E21>=Q$9),IF(AND(ISNUMBER($J21),Q$9<=$D21+($E21-$D21+1)*$J21-1),2,1),0) -> 0 | R21: =IF(AND($D21<=R$9+6,$E21>=R$9),IF(AND(ISNUMBER($J21),R$9<=$D21+($E21-$D21+1)*$J21-1),2,1),0) -> 0 | S21: =IF(AND($D21<=S$9+6,$E21>=S$9),IF(AND(ISNUMBER($J21),S$9<=$D21+($E21-$D21+1)*$J21-1),2,1),0) -> 0 | T21: =IF(AND($D21<=T$9+6,$E21>=T$9),IF(AND(ISNUMBER($J21),T$9<=$D21+($E21-$D21+1)*$J21-1),2,1),0) -> 0 | ... AB21: =IF(AND($D21<=AB$9+6,$E21>=AB$9),IF(AND(ISNUMBER($J21),AB$9<=$D21+($E21-$D21+1)*$J21-1),2,1),0) -> 0
A22: SCRUM-18 | B22: Selección de modo de uso | C22: Benjamín | D22: =IF('Datos Jira'!G21="",'Datos Jira'!J21,'Datos Jira'!G21) -> 46273 | E22: =IF('Datos Jira'!H21="",'Datos Jira'!K21,'Datos Jira'!H21) -> 46295 | F22: Mixto | G22: ='Datos Jira'!E21 -> Finalizado | H22: =COUNTIFS('Datos Jira'!$B$8:$B$234,A22) -> 5 | I22: =COUNTIFS('Datos Jira'!$B$8:$B$234,A22,'Datos Jira'!$E$8:$E$234,"Finalizado") -> 5 | J22: =IF(G22="Finalizado",1,IF(H22>0,I22/H22,IF(G22="Pendiente",0,""))) -> 1 | K22: =E22-D22+1 -> 23 | M22: =IF(AND($D22<=M$9+6,$E22>=M$9),IF(AND(ISNUMBER($J22),M$9<=$D22+($E22-$D22+1)*$J22-1),2,1),0) -> 0 | N22: =IF(AND($D22<=N$9+6,$E22>=N$9),IF(AND(ISNUMBER($J22),N$9<=$D22+($E22-$D22+1)*$J22-1),2,1),0) -> 2 | O22: =IF(AND($D22<=O$9+6,$E22>=O$9),IF(AND(ISNUMBER($J22),O$9<=$D22+($E22-$D22+1)*$J22-1),2,1),0) -> 2 | P22: =IF(AND($D22<=P$9+6,$E22>=P$9),IF(AND(ISNUMBER($J22),P$9<=$D22+($E22-$D22+1)*$J22-1),2,1),0) -> 2 | Q22: =IF(AND($D22<=Q$9+6,$E22>=Q$9),IF(AND(ISNUMBER($J22),Q$9<=$D22+($E22-$D22+1)*$J22-1),2,1),0) -> 2 | R22: =IF(AND($D22<=R$9+6,$E22>=R$9),IF(AND(ISNUMBER($J22),R$9<=$D22+($E22-$D22+1)*$J22-1),2,1),0) -> 0 | S22: =IF(AND($D22<=S$9+6,$E22>=S$9),IF(AND(ISNUMBER($J22),S$9<=$D22+($E22-$D22+1)*$J22-1),2,1),0) -> 0 | T22: =IF(AND($D22<=T$9+6,$E22>=T$9),IF(AND(ISNUMBER($J22),T$9<=$D22+($E22-$D22+1)*$J22-1),2,1),0) -> 0 | ... AB22: =IF(AND($D22<=AB$9+6,$E22>=AB$9),IF(AND(ISNUMBER($J22),AB$9<=$D22+($E22-$D22+1)*$J22-1),2,1),0) -> 0
A23: SCRUM-19 | B23: Generación UUID anónimo | C23: Daniela | D23: =IF('Datos Jira'!G22="",'Datos Jira'!J22,'Datos Jira'!G22) -> 46273 | E23: =IF('Datos Jira'!H22="",'Datos Jira'!K22,'Datos Jira'!H22) -> 46293 | F23: Mixto | G23: ='Datos Jira'!E22 -> Finalizado | H23: =COUNTIFS('Datos Jira'!$B$8:$B$234,A23) -> 4 | I23: =COUNTIFS('Datos Jira'!$B$8:$B$234,A23,'Datos Jira'!$E$8:$E$234,"Finalizado") -> 4 | J23: =IF(G23="Finalizado",1,IF(H23>0,I23/H23,IF(G23="Pendiente",0,""))) -> 1 | K23: =E23-D23+1 -> 21 | M23: =IF(AND($D23<=M$9+6,$E23>=M$9),IF(AND(ISNUMBER($J23),M$9<=$D23+($E23-$D23+1)*$J23-1),2,1),0) -> 0 | N23: =IF(AND($D23<=N$9+6,$E23>=N$9),IF(AND(ISNUMBER($J23),N$9<=$D23+($E23-$D23+1)*$J23-1),2,1),0) -> 2 | O23: =IF(AND($D23<=O$9+6,$E23>=O$9),IF(AND(ISNUMBER($J23),O$9<=$D23+($E23-$D23+1)*$J23-1),2,1),0) -> 2 | P23: =IF(AND($D23<=P$9+6,$E23>=P$9),IF(AND(ISNUMBER($J23),P$9<=$D23+($E23-$D23+1)*$J23-1),2,1),0) -> 2 | Q23: =IF(AND($D23<=Q$9+6,$E23>=Q$9),IF(AND(ISNUMBER($J23),Q$9<=$D23+($E23-$D23+1)*$J23-1),2,1),0) -> 2 | R23: =IF(AND($D23<=R$9+6,$E23>=R$9),IF(AND(ISNUMBER($J23),R$9<=$D23+($E23-$D23+1)*$J23-1),2,1),0) -> 0 | S23: =IF(AND($D23<=S$9+6,$E23>=S$9),IF(AND(ISNUMBER($J23),S$9<=$D23+($E23-$D23+1)*$J23-1),2,1),0) -> 0 | T23: =IF(AND($D23<=T$9+6,$E23>=T$9),IF(AND(ISNUMBER($J23),T$9<=$D23+($E23-$D23+1)*$J23-1),2,1),0) -> 0 | ... AB23: =IF(AND($D23<=AB$9+6,$E23>=AB$9),IF(AND(ISNUMBER($J23),AB$9<=$D23+($E23-$D23+1)*$J23-1),2,1),0) -> 0
A24: SCRUM-20 | B24: Prototipo Figma – Flujos Completos 9 - 12 | C24: Daniela | D24: =IF('Datos Jira'!G23="",'Datos Jira'!J23,'Datos Jira'!G23) -> 46273 | E24: =IF('Datos Jira'!H23="",'Datos Jira'!K23,'Datos Jira'!H23) -> 46299 | F24: Mixto | G24: ='Datos Jira'!E23 -> Finalizado | H24: =COUNTIFS('Datos Jira'!$B$8:$B$234,A24) -> 8 | I24: =COUNTIFS('Datos Jira'!$B$8:$B$234,A24,'Datos Jira'!$E$8:$E$234,"Finalizado") -> 8 | J24: =IF(G24="Finalizado",1,IF(H24>0,I24/H24,IF(G24="Pendiente",0,""))) -> 1 | K24: =E24-D24+1 -> 27 | M24: =IF(AND($D24<=M$9+6,$E24>=M$9),IF(AND(ISNUMBER($J24),M$9<=$D24+($E24-$D24+1)*$J24-1),2,1),0) -> 0 | N24: =IF(AND($D24<=N$9+6,$E24>=N$9),IF(AND(ISNUMBER($J24),N$9<=$D24+($E24-$D24+1)*$J24-1),2,1),0) -> 2 | O24: =IF(AND($D24<=O$9+6,$E24>=O$9),IF(AND(ISNUMBER($J24),O$9<=$D24+($E24-$D24+1)*$J24-1),2,1),0) -> 2 | P24: =IF(AND($D24<=P$9+6,$E24>=P$9),IF(AND(ISNUMBER($J24),P$9<=$D24+($E24-$D24+1)*$J24-1),2,1),0) -> 2 | Q24: =IF(AND($D24<=Q$9+6,$E24>=Q$9),IF(AND(ISNUMBER($J24),Q$9<=$D24+($E24-$D24+1)*$J24-1),2,1),0) -> 2 | R24: =IF(AND($D24<=R$9+6,$E24>=R$9),IF(AND(ISNUMBER($J24),R$9<=$D24+($E24-$D24+1)*$J24-1),2,1),0) -> 0 | S24: =IF(AND($D24<=S$9+6,$E24>=S$9),IF(AND(ISNUMBER($J24),S$9<=$D24+($E24-$D24+1)*$J24-1),2,1),0) -> 0 | T24: =IF(AND($D24<=T$9+6,$E24>=T$9),IF(AND(ISNUMBER($J24),T$9<=$D24+($E24-$D24+1)*$J24-1),2,1),0) -> 0 | ... AB24: =IF(AND($D24<=AB$9+6,$E24>=AB$9),IF(AND(ISNUMBER($J24),AB$9<=$D24+($E24-$D24+1)*$J24-1),2,1),0) -> 0
A25: SCRUM-85 | B25: Registro de Cuidador | C25: Eduardo | D25: =IF('Datos Jira'!G87="",'Datos Jira'!J87,'Datos Jira'!G87) -> 46273 | E25: =IF('Datos Jira'!H87="",'Datos Jira'!K87,'Datos Jira'!H87) -> 46295 | F25: Mixto | G25: ='Datos Jira'!E87 -> Finalizado | H25: =COUNTIFS('Datos Jira'!$B$8:$B$234,A25) -> 6 | I25: =COUNTIFS('Datos Jira'!$B$8:$B$234,A25,'Datos Jira'!$E$8:$E$234,"Finalizado") -> 6 | J25: =IF(G25="Finalizado",1,IF(H25>0,I25/H25,IF(G25="Pendiente",0,""))) -> 1 | K25: =E25-D25+1 -> 23 | M25: =IF(AND($D25<=M$9+6,$E25>=M$9),IF(AND(ISNUMBER($J25),M$9<=$D25+($E25-$D25+1)*$J25-1),2,1),0) -> 0 | N25: =IF(AND($D25<=N$9+6,$E25>=N$9),IF(AND(ISNUMBER($J25),N$9<=$D25+($E25-$D25+1)*$J25-1),2,1),0) -> 2 | O25: =IF(AND($D25<=O$9+6,$E25>=O$9),IF(AND(ISNUMBER($J25),O$9<=$D25+($E25-$D25+1)*$J25-1),2,1),0) -> 2 | P25: =IF(AND($D25<=P$9+6,$E25>=P$9),IF(AND(ISNUMBER($J25),P$9<=$D25+($E25-$D25+1)*$J25-1),2,1),0) -> 2 | Q25: =IF(AND($D25<=Q$9+6,$E25>=Q$9),IF(AND(ISNUMBER($J25),Q$9<=$D25+($E25-$D25+1)*$J25-1),2,1),0) -> 2 | R25: =IF(AND($D25<=R$9+6,$E25>=R$9),IF(AND(ISNUMBER($J25),R$9<=$D25+($E25-$D25+1)*$J25-1),2,1),0) -> 0 | S25: =IF(AND($D25<=S$9+6,$E25>=S$9),IF(AND(ISNUMBER($J25),S$9<=$D25+($E25-$D25+1)*$J25-1),2,1),0) -> 0 | T25: =IF(AND($D25<=T$9+6,$E25>=T$9),IF(AND(ISNUMBER($J25),T$9<=$D25+($E25-$D25+1)*$J25-1),2,1),0) -> 0 | ... AB25: =IF(AND($D25<=AB$9+6,$E25>=AB$9),IF(AND(ISNUMBER($J25),AB$9<=$D25+($E25-$D25+1)*$J25-1),2,1),0) -> 0
A26: SCRUM-124 | B26: Desbloqueo de Tareas de Programación | C26: Daniela | D26: =IF('Datos Jira'!G119="",'Datos Jira'!J119,'Datos Jira'!G119) -> 46273 | E26: =IF('Datos Jira'!H119="",'Datos Jira'!K119,'Datos Jira'!H119) -> 46299 | F26: Mixto | G26: ='Datos Jira'!E119 -> Finalizado | H26: =COUNTIFS('Datos Jira'!$B$8:$B$234,A26) -> 4 | I26: =COUNTIFS('Datos Jira'!$B$8:$B$234,A26,'Datos Jira'!$E$8:$E$234,"Finalizado") -> 4 | J26: =IF(G26="Finalizado",1,IF(H26>0,I26/H26,IF(G26="Pendiente",0,""))) -> 1 | K26: =E26-D26+1 -> 27 | M26: =IF(AND($D26<=M$9+6,$E26>=M$9),IF(AND(ISNUMBER($J26),M$9<=$D26+($E26-$D26+1)*$J26-1),2,1),0) -> 0 | N26: =IF(AND($D26<=N$9+6,$E26>=N$9),IF(AND(ISNUMBER($J26),N$9<=$D26+($E26-$D26+1)*$J26-1),2,1),0) -> 2 | O26: =IF(AND($D26<=O$9+6,$E26>=O$9),IF(AND(ISNUMBER($J26),O$9<=$D26+($E26-$D26+1)*$J26-1),2,1),0) -> 2 | P26: =IF(AND($D26<=P$9+6,$E26>=P$9),IF(AND(ISNUMBER($J26),P$9<=$D26+($E26-$D26+1)*$J26-1),2,1),0) -> 2 | Q26: =IF(AND($D26<=Q$9+6,$E26>=Q$9),IF(AND(ISNUMBER($J26),Q$9<=$D26+($E26-$D26+1)*$J26-1),2,1),0) -> 2 | R26: =IF(AND($D26<=R$9+6,$E26>=R$9),IF(AND(ISNUMBER($J26),R$9<=$D26+($E26-$D26+1)*$J26-1),2,1),0) -> 0 | S26: =IF(AND($D26<=S$9+6,$E26>=S$9),IF(AND(ISNUMBER($J26),S$9<=$D26+($E26-$D26+1)*$J26-1),2,1),0) -> 0 | T26: =IF(AND($D26<=T$9+6,$E26>=T$9),IF(AND(ISNUMBER($J26),T$9<=$D26+($E26-$D26+1)*$J26-1),2,1),0) -> 0 | ... AB26: =IF(AND($D26<=AB$9+6,$E26>=AB$9),IF(AND(ISNUMBER($J26),AB$9<=$D26+($E26-$D26+1)*$J26-1),2,1),0) -> 0
A27: SCRUM-129 | B27: Prototipo Figma - Flujos Completos 1-4 | C27: Benjamín | D27: =IF('Datos Jira'!G124="",'Datos Jira'!J124,'Datos Jira'!G124) -> 46273 | E27: =IF('Datos Jira'!H124="",'Datos Jira'!K124,'Datos Jira'!H124) -> 46301 | F27: Mixto | G27: ='Datos Jira'!E124 -> Finalizado | H27: =COUNTIFS('Datos Jira'!$B$8:$B$234,A27) -> 8 | I27: =COUNTIFS('Datos Jira'!$B$8:$B$234,A27,'Datos Jira'!$E$8:$E$234,"Finalizado") -> 8 | J27: =IF(G27="Finalizado",1,IF(H27>0,I27/H27,IF(G27="Pendiente",0,""))) -> 1 | K27: =E27-D27+1 -> 29 | M27: =IF(AND($D27<=M$9+6,$E27>=M$9),IF(AND(ISNUMBER($J27),M$9<=$D27+($E27-$D27+1)*$J27-1),2,1),0) -> 0 | N27: =IF(AND($D27<=N$9+6,$E27>=N$9),IF(AND(ISNUMBER($J27),N$9<=$D27+($E27-$D27+1)*$J27-1),2,1),0) -> 2 | O27: =IF(AND($D27<=O$9+6,$E27>=O$9),IF(AND(ISNUMBER($J27),O$9<=$D27+($E27-$D27+1)*$J27-1),2,1),0) -> 2 | P27: =IF(AND($D27<=P$9+6,$E27>=P$9),IF(AND(ISNUMBER($J27),P$9<=$D27+($E27-$D27+1)*$J27-1),2,1),0) -> 2 | Q27: =IF(AND($D27<=Q$9+6,$E27>=Q$9),IF(AND(ISNUMBER($J27),Q$9<=$D27+($E27-$D27+1)*$J27-1),2,1),0) -> 2 | R27: =IF(AND($D27<=R$9+6,$E27>=R$9),IF(AND(ISNUMBER($J27),R$9<=$D27+($E27-$D27+1)*$J27-1),2,1),0) -> 2 | S27: =IF(AND($D27<=S$9+6,$E27>=S$9),IF(AND(ISNUMBER($J27),S$9<=$D27+($E27-$D27+1)*$J27-1),2,1),0) -> 0 | T27: =IF(AND($D27<=T$9+6,$E27>=T$9),IF(AND(ISNUMBER($J27),T$9<=$D27+($E27-$D27+1)*$J27-1),2,1),0) -> 0 | ... AB27: =IF(AND($D27<=AB$9+6,$E27>=AB$9),IF(AND(ISNUMBER($J27),AB$9<=$D27+($E27-$D27+1)*$J27-1),2,1),0) -> 0
A28: SCRUM-130 | B28: Prototipo Figma - Flujos Completos 5 - 8 | C28: Eduardo | D28: =IF('Datos Jira'!G125="",'Datos Jira'!J125,'Datos Jira'!G125) -> 46273 | E28: =IF('Datos Jira'!H125="",'Datos Jira'!K125,'Datos Jira'!H125) -> 46301 | F28: Mixto | G28: ='Datos Jira'!E125 -> Finalizado | H28: =COUNTIFS('Datos Jira'!$B$8:$B$234,A28) -> 6 | I28: =COUNTIFS('Datos Jira'!$B$8:$B$234,A28,'Datos Jira'!$E$8:$E$234,"Finalizado") -> 6 | J28: =IF(G28="Finalizado",1,IF(H28>0,I28/H28,IF(G28="Pendiente",0,""))) -> 1 | K28: =E28-D28+1 -> 29 | M28: =IF(AND($D28<=M$9+6,$E28>=M$9),IF(AND(ISNUMBER($J28),M$9<=$D28+($E28-$D28+1)*$J28-1),2,1),0) -> 0 | N28: =IF(AND($D28<=N$9+6,$E28>=N$9),IF(AND(ISNUMBER($J28),N$9<=$D28+($E28-$D28+1)*$J28-1),2,1),0) -> 2 | O28: =IF(AND($D28<=O$9+6,$E28>=O$9),IF(AND(ISNUMBER($J28),O$9<=$D28+($E28-$D28+1)*$J28-1),2,1),0) -> 2 | P28: =IF(AND($D28<=P$9+6,$E28>=P$9),IF(AND(ISNUMBER($J28),P$9<=$D28+($E28-$D28+1)*$J28-1),2,1),0) -> 2 | Q28: =IF(AND($D28<=Q$9+6,$E28>=Q$9),IF(AND(ISNUMBER($J28),Q$9<=$D28+($E28-$D28+1)*$J28-1),2,1),0) -> 2 | R28: =IF(AND($D28<=R$9+6,$E28>=R$9),IF(AND(ISNUMBER($J28),R$9<=$D28+($E28-$D28+1)*$J28-1),2,1),0) -> 2 | S28: =IF(AND($D28<=S$9+6,$E28>=S$9),IF(AND(ISNUMBER($J28),S$9<=$D28+($E28-$D28+1)*$J28-1),2,1),0) -> 0 | T28: =IF(AND($D28<=T$9+6,$E28>=T$9),IF(AND(ISNUMBER($J28),T$9<=$D28+($E28-$D28+1)*$J28-1),2,1),0) -> 0 | ... AB28: =IF(AND($D28<=AB$9+6,$E28>=AB$9),IF(AND(ISNUMBER($J28),AB$9<=$D28+($E28-$D28+1)*$J28-1),2,1),0) -> 0
A29: SCRUM-139 | B29: Paso a Producción – Merge Develop -> Main | C29: Daniela | D29: =IF('Datos Jira'!G134="",'Datos Jira'!J134,'Datos Jira'!G134) -> 46273 | E29: =IF('Datos Jira'!H134="",'Datos Jira'!K134,'Datos Jira'!H134) -> 46301 | F29: Sprint | G29: ='Datos Jira'!E134 -> Finalizado | H29: =COUNTIFS('Datos Jira'!$B$8:$B$234,A29) -> 0 | I29: =COUNTIFS('Datos Jira'!$B$8:$B$234,A29,'Datos Jira'!$E$8:$E$234,"Finalizado") -> 0 | J29: =IF(G29="Finalizado",1,IF(H29>0,I29/H29,IF(G29="Pendiente",0,""))) -> 1 | K29: =E29-D29+1 -> 29 | M29: =IF(AND($D29<=M$9+6,$E29>=M$9),IF(AND(ISNUMBER($J29),M$9<=$D29+($E29-$D29+1)*$J29-1),2,1),0) -> 0 | N29: =IF(AND($D29<=N$9+6,$E29>=N$9),IF(AND(ISNUMBER($J29),N$9<=$D29+($E29-$D29+1)*$J29-1),2,1),0) -> 2 | O29: =IF(AND($D29<=O$9+6,$E29>=O$9),IF(AND(ISNUMBER($J29),O$9<=$D29+($E29-$D29+1)*$J29-1),2,1),0) -> 2 | P29: =IF(AND($D29<=P$9+6,$E29>=P$9),IF(AND(ISNUMBER($J29),P$9<=$D29+($E29-$D29+1)*$J29-1),2,1),0) -> 2 | Q29: =IF(AND($D29<=Q$9+6,$E29>=Q$9),IF(AND(ISNUMBER($J29),Q$9<=$D29+($E29-$D29+1)*$J29-1),2,1),0) -> 2 | R29: =IF(AND($D29<=R$9+6,$E29>=R$9),IF(AND(ISNUMBER($J29),R$9<=$D29+($E29-$D29+1)*$J29-1),2,1),0) -> 2 | S29: =IF(AND($D29<=S$9+6,$E29>=S$9),IF(AND(ISNUMBER($J29),S$9<=$D29+($E29-$D29+1)*$J29-1),2,1),0) -> 0 | T29: =IF(AND($D29<=T$9+6,$E29>=T$9),IF(AND(ISNUMBER($J29),T$9<=$D29+($E29-$D29+1)*$J29-1),2,1),0) -> 0 | ... AB29: =IF(AND($D29<=AB$9+6,$E29>=AB$9),IF(AND(ISNUMBER($J29),AB$9<=$D29+($E29-$D29+1)*$J29-1),2,1),0) -> 0
B30: Juegos y métricas
A31: SCRUM-21 | B31: Juegos (Memoria) | C31: Benjamín | D31: =IF('Datos Jira'!G24="",'Datos Jira'!J24,'Datos Jira'!G24) -> 46307 | E31: =IF('Datos Jira'!H24="",'Datos Jira'!K24,'Datos Jira'!H24) -> 46318 | F31: Jira | G31: ='Datos Jira'!E24 -> En curso | H31: =COUNTIFS('Datos Jira'!$B$8:$B$234,A31) -> 8 | I31: =COUNTIFS('Datos Jira'!$B$8:$B$234,A31,'Datos Jira'!$E$8:$E$234,"Finalizado") -> 0 | J31: =IF(G31="Finalizado",1,IF(H31>0,I31/H31,IF(G31="Pendiente",0,""))) -> 0 | K31: =E31-D31+1 -> 12 | M31: =IF(AND($D31<=M$9+6,$E31>=M$9),IF(AND(ISNUMBER($J31),M$9<=$D31+($E31-$D31+1)*$J31-1),2,1),0) -> 0 | N31: =IF(AND($D31<=N$9+6,$E31>=N$9),IF(AND(ISNUMBER($J31),N$9<=$D31+($E31-$D31+1)*$J31-1),2,1),0) -> 0 | O31: =IF(AND($D31<=O$9+6,$E31>=O$9),IF(AND(ISNUMBER($J31),O$9<=$D31+($E31-$D31+1)*$J31-1),2,1),0) -> 0 | P31: =IF(AND($D31<=P$9+6,$E31>=P$9),IF(AND(ISNUMBER($J31),P$9<=$D31+($E31-$D31+1)*$J31-1),2,1),0) -> 0 | Q31: =IF(AND($D31<=Q$9+6,$E31>=Q$9),IF(AND(ISNUMBER($J31),Q$9<=$D31+($E31-$D31+1)*$J31-1),2,1),0) -> 0 | R31: =IF(AND($D31<=R$9+6,$E31>=R$9),IF(AND(ISNUMBER($J31),R$9<=$D31+($E31-$D31+1)*$J31-1),2,1),0) -> 0 | S31: =IF(AND($D31<=S$9+6,$E31>=S$9),IF(AND(ISNUMBER($J31),S$9<=$D31+($E31-$D31+1)*$J31-1),2,1),0) -> 1 | T31: =IF(AND($D31<=T$9+6,$E31>=T$9),IF(AND(ISNUMBER($J31),T$9<=$D31+($E31-$D31+1)*$J31-1),2,1),0) -> 1 | ... AB31: =IF(AND($D31<=AB$9+6,$E31>=AB$9),IF(AND(ISNUMBER($J31),AB$9<=$D31+($E31-$D31+1)*$J31-1),2,1),0) -> 0
A32: SCRUM-22 | B32: Juegos (Praxias) | C32: Daniela | D32: =IF('Datos Jira'!G25="",'Datos Jira'!J25,'Datos Jira'!G25) -> 46307 | E32: =IF('Datos Jira'!H25="",'Datos Jira'!K25,'Datos Jira'!H25) -> 46318 | F32: Jira | G32: ='Datos Jira'!E25 -> Finalizado | H32: =COUNTIFS('Datos Jira'!$B$8:$B$234,A32) -> 8 | I32: =COUNTIFS('Datos Jira'!$B$8:$B$234,A32,'Datos Jira'!$E$8:$E$234,"Finalizado") -> 8 | J32: =IF(G32="Finalizado",1,IF(H32>0,I32/H32,IF(G32="Pendiente",0,""))) -> 1 | K32: =E32-D32+1 -> 12 | M32: =IF(AND($D32<=M$9+6,$E32>=M$9),IF(AND(ISNUMBER($J32),M$9<=$D32+($E32-$D32+1)*$J32-1),2,1),0) -> 0 | N32: =IF(AND($D32<=N$9+6,$E32>=N$9),IF(AND(ISNUMBER($J32),N$9<=$D32+($E32-$D32+1)*$J32-1),2,1),0) -> 0 | O32: =IF(AND($D32<=O$9+6,$E32>=O$9),IF(AND(ISNUMBER($J32),O$9<=$D32+($E32-$D32+1)*$J32-1),2,1),0) -> 0 | P32: =IF(AND($D32<=P$9+6,$E32>=P$9),IF(AND(ISNUMBER($J32),P$9<=$D32+($E32-$D32+1)*$J32-1),2,1),0) -> 0 | Q32: =IF(AND($D32<=Q$9+6,$E32>=Q$9),IF(AND(ISNUMBER($J32),Q$9<=$D32+($E32-$D32+1)*$J32-1),2,1),0) -> 0 | R32: =IF(AND($D32<=R$9+6,$E32>=R$9),IF(AND(ISNUMBER($J32),R$9<=$D32+($E32-$D32+1)*$J32-1),2,1),0) -> 0 | S32: =IF(AND($D32<=S$9+6,$E32>=S$9),IF(AND(ISNUMBER($J32),S$9<=$D32+($E32-$D32+1)*$J32-1),2,1),0) -> 2 | T32: =IF(AND($D32<=T$9+6,$E32>=T$9),IF(AND(ISNUMBER($J32),T$9<=$D32+($E32-$D32+1)*$J32-1),2,1),0) -> 2 | ... AB32: =IF(AND($D32<=AB$9+6,$E32>=AB$9),IF(AND(ISNUMBER($J32),AB$9<=$D32+($E32-$D32+1)*$J32-1),2,1),0) -> 0
A33: SCRUM-23 | B33: Juegos (Atención) | C33: Eduardo | D33: =IF('Datos Jira'!G26="",'Datos Jira'!J26,'Datos Jira'!G26) -> 46307 | E33: =IF('Datos Jira'!H26="",'Datos Jira'!K26,'Datos Jira'!H26) -> 46318 | F33: Jira | G33: ='Datos Jira'!E26 -> En curso | H33: =COUNTIFS('Datos Jira'!$B$8:$B$234,A33) -> 5 | I33: =COUNTIFS('Datos Jira'!$B$8:$B$234,A33,'Datos Jira'!$E$8:$E$234,"Finalizado") -> 4 | J33: =IF(G33="Finalizado",1,IF(H33>0,I33/H33,IF(G33="Pendiente",0,""))) -> 0.8 | K33: =E33-D33+1 -> 12 | M33: =IF(AND($D33<=M$9+6,$E33>=M$9),IF(AND(ISNUMBER($J33),M$9<=$D33+($E33-$D33+1)*$J33-1),2,1),0) -> 0 | N33: =IF(AND($D33<=N$9+6,$E33>=N$9),IF(AND(ISNUMBER($J33),N$9<=$D33+($E33-$D33+1)*$J33-1),2,1),0) -> 0 | O33: =IF(AND($D33<=O$9+6,$E33>=O$9),IF(AND(ISNUMBER($J33),O$9<=$D33+($E33-$D33+1)*$J33-1),2,1),0) -> 0 | P33: =IF(AND($D33<=P$9+6,$E33>=P$9),IF(AND(ISNUMBER($J33),P$9<=$D33+($E33-$D33+1)*$J33-1),2,1),0) -> 0 | Q33: =IF(AND($D33<=Q$9+6,$E33>=Q$9),IF(AND(ISNUMBER($J33),Q$9<=$D33+($E33-$D33+1)*$J33-1),2,1),0) -> 0 | R33: =IF(AND($D33<=R$9+6,$E33>=R$9),IF(AND(ISNUMBER($J33),R$9<=$D33+($E33-$D33+1)*$J33-1),2,1),0) -> 0 | S33: =IF(AND($D33<=S$9+6,$E33>=S$9),IF(AND(ISNUMBER($J33),S$9<=$D33+($E33-$D33+1)*$J33-1),2,1),0) -> 2 | T33: =IF(AND($D33<=T$9+6,$E33>=T$9),IF(AND(ISNUMBER($J33),T$9<=$D33+($E33-$D33+1)*$J33-1),2,1),0) -> 2 | ... AB33: =IF(AND($D33<=AB$9+6,$E33>=AB$9),IF(AND(ISNUMBER($J33),AB$9<=$D33+($E33-$D33+1)*$J33-1),2,1),0) -> 0
A34: SCRUM-24 | B34: Módulo de respiración guiada | C34: Benjamín | D34: =IF('Datos Jira'!G27="",'Datos Jira'!J27,'Datos Jira'!G27) -> 46307 | E34: =IF('Datos Jira'!H27="",'Datos Jira'!K27,'Datos Jira'!H27) -> 46318 | F34: Jira | G34: ='Datos Jira'!E27 -> Finalizado | H34: =COUNTIFS('Datos Jira'!$B$8:$B$234,A34) -> 8 | I34: =COUNTIFS('Datos Jira'!$B$8:$B$234,A34,'Datos Jira'!$E$8:$E$234,"Finalizado") -> 8 | J34: =IF(G34="Finalizado",1,IF(H34>0,I34/H34,IF(G34="Pendiente",0,""))) -> 1 | K34: =E34-D34+1 -> 12 | M34: =IF(AND($D34<=M$9+6,$E34>=M$9),IF(AND(ISNUMBER($J34),M$9<=$D34+($E34-$D34+1)*$J34-1),2,1),0) -> 0 | N34: =IF(AND($D34<=N$9+6,$E34>=N$9),IF(AND(ISNUMBER($J34),N$9<=$D34+($E34-$D34+1)*$J34-1),2,1),0) -> 0 | O34: =IF(AND($D34<=O$9+6,$E34>=O$9),IF(AND(ISNUMBER($J34),O$9<=$D34+($E34-$D34+1)*$J34-1),2,1),0) -> 0 | P34: =IF(AND($D34<=P$9+6,$E34>=P$9),IF(AND(ISNUMBER($J34),P$9<=$D34+($E34-$D34+1)*$J34-1),2,1),0) -> 0 | Q34: =IF(AND($D34<=Q$9+6,$E34>=Q$9),IF(AND(ISNUMBER($J34),Q$9<=$D34+($E34-$D34+1)*$J34-1),2,1),0) -> 0 | R34: =IF(AND($D34<=R$9+6,$E34>=R$9),IF(AND(ISNUMBER($J34),R$9<=$D34+($E34-$D34+1)*$J34-1),2,1),0) -> 0 | S34: =IF(AND($D34<=S$9+6,$E34>=S$9),IF(AND(ISNUMBER($J34),S$9<=$D34+($E34-$D34+1)*$J34-1),2,1),0) -> 2 | T34: =IF(AND($D34<=T$9+6,$E34>=T$9),IF(AND(ISNUMBER($J34),T$9<=$D34+($E34-$D34+1)*$J34-1),2,1),0) -> 2 | ... AB34: =IF(AND($D34<=AB$9+6,$E34>=AB$9),IF(AND(ISNUMBER($J34),AB$9<=$D34+($E34-$D34+1)*$J34-1),2,1),0) -> 0
A35: SCRUM-25 | B35: Captura de métricas por sesión | C35: Daniela | D35: =IF('Datos Jira'!G28="",'Datos Jira'!J28,'Datos Jira'!G28) -> 46300 | E35: =IF('Datos Jira'!H28="",'Datos Jira'!K28,'Datos Jira'!H28) -> 46308 | F35: Jira | G35: ='Datos Jira'!E28 -> Finalizado | H35: =COUNTIFS('Datos Jira'!$B$8:$B$234,A35) -> 6 | I35: =COUNTIFS('Datos Jira'!$B$8:$B$234,A35,'Datos Jira'!$E$8:$E$234,"Finalizado") -> 6 | J35: =IF(G35="Finalizado",1,IF(H35>0,I35/H35,IF(G35="Pendiente",0,""))) -> 1 | K35: =E35-D35+1 -> 9 | M35: =IF(AND($D35<=M$9+6,$E35>=M$9),IF(AND(ISNUMBER($J35),M$9<=$D35+($E35-$D35+1)*$J35-1),2,1),0) -> 0 | N35: =IF(AND($D35<=N$9+6,$E35>=N$9),IF(AND(ISNUMBER($J35),N$9<=$D35+($E35-$D35+1)*$J35-1),2,1),0) -> 0 | O35: =IF(AND($D35<=O$9+6,$E35>=O$9),IF(AND(ISNUMBER($J35),O$9<=$D35+($E35-$D35+1)*$J35-1),2,1),0) -> 0 | P35: =IF(AND($D35<=P$9+6,$E35>=P$9),IF(AND(ISNUMBER($J35),P$9<=$D35+($E35-$D35+1)*$J35-1),2,1),0) -> 0 | Q35: =IF(AND($D35<=Q$9+6,$E35>=Q$9),IF(AND(ISNUMBER($J35),Q$9<=$D35+($E35-$D35+1)*$J35-1),2,1),0) -> 0 | R35: =IF(AND($D35<=R$9+6,$E35>=R$9),IF(AND(ISNUMBER($J35),R$9<=$D35+($E35-$D35+1)*$J35-1),2,1),0) -> 2 | S35: =IF(AND($D35<=S$9+6,$E35>=S$9),IF(AND(ISNUMBER($J35),S$9<=$D35+($E35-$D35+1)*$J35-1),2,1),0) -> 2 | T35: =IF(AND($D35<=T$9+6,$E35>=T$9),IF(AND(ISNUMBER($J35),T$9<=$D35+($E35-$D35+1)*$J35-1),2,1),0) -> 0 | ... AB35: =IF(AND($D35<=AB$9+6,$E35>=AB$9),IF(AND(ISNUMBER($J35),AB$9<=$D35+($E35-$D35+1)*$J35-1),2,1),0) -> 0
A36: SCRUM-26 | B36: Pruebas QA | C36: Eduardo | D36: =IF('Datos Jira'!G29="",'Datos Jira'!J29,'Datos Jira'!G29) -> 46318 | E36: =IF('Datos Jira'!H29="",'Datos Jira'!K29,'Datos Jira'!H29) -> 46320 | F36: Jira | G36: ='Datos Jira'!E29 -> Pendiente | H36: =COUNTIFS('Datos Jira'!$B$8:$B$234,A36) -> 8 | I36: =COUNTIFS('Datos Jira'!$B$8:$B$234,A36,'Datos Jira'!$E$8:$E$234,"Finalizado") -> 0 | J36: =IF(G36="Finalizado",1,IF(H36>0,I36/H36,IF(G36="Pendiente",0,""))) -> 0 | K36: =E36-D36+1 -> 3 | M36: =IF(AND($D36<=M$9+6,$E36>=M$9),IF(AND(ISNUMBER($J36),M$9<=$D36+($E36-$D36+1)*$J36-1),2,1),0) -> 0 | N36: =IF(AND($D36<=N$9+6,$E36>=N$9),IF(AND(ISNUMBER($J36),N$9<=$D36+($E36-$D36+1)*$J36-1),2,1),0) -> 0 | O36: =IF(AND($D36<=O$9+6,$E36>=O$9),IF(AND(ISNUMBER($J36),O$9<=$D36+($E36-$D36+1)*$J36-1),2,1),0) -> 0 | P36: =IF(AND($D36<=P$9+6,$E36>=P$9),IF(AND(ISNUMBER($J36),P$9<=$D36+($E36-$D36+1)*$J36-1),2,1),0) -> 0 | Q36: =IF(AND($D36<=Q$9+6,$E36>=Q$9),IF(AND(ISNUMBER($J36),Q$9<=$D36+($E36-$D36+1)*$J36-1),2,1),0) -> 0 | R36: =IF(AND($D36<=R$9+6,$E36>=R$9),IF(AND(ISNUMBER($J36),R$9<=$D36+($E36-$D36+1)*$J36-1),2,1),0) -> 0 | S36: =IF(AND($D36<=S$9+6,$E36>=S$9),IF(AND(ISNUMBER($J36),S$9<=$D36+($E36-$D36+1)*$J36-1),2,1),0) -> 0 | T36: =IF(AND($D36<=T$9+6,$E36>=T$9),IF(AND(ISNUMBER($J36),T$9<=$D36+($E36-$D36+1)*$J36-1),2,1),0) -> 2 | ... AB36: =IF(AND($D36<=AB$9+6,$E36>=AB$9),IF(AND(ISNUMBER($J36),AB$9<=$D36+($E36-$D36+1)*$J36-1),2,1),0) -> 0
A37: SCRUM-28 | B37: FastAPI - endpoint/session/analyze | C37: Daniela | D37: =IF('Datos Jira'!G30="",'Datos Jira'!J30,'Datos Jira'!G30) -> 46302 | E37: =IF('Datos Jira'!H30="",'Datos Jira'!K30,'Datos Jira'!H30) -> 46308 | F37: Jira | G37: ='Datos Jira'!E30 -> Finalizado | H37: =COUNTIFS('Datos Jira'!$B$8:$B$234,A37) -> 6 | I37: =COUNTIFS('Datos Jira'!$B$8:$B$234,A37,'Datos Jira'!$E$8:$E$234,"Finalizado") -> 6 | J37: =IF(G37="Finalizado",1,IF(H37>0,I37/H37,IF(G37="Pendiente",0,""))) -> 1 | K37: =E37-D37+1 -> 7 | M37: =IF(AND($D37<=M$9+6,$E37>=M$9),IF(AND(ISNUMBER($J37),M$9<=$D37+($E37-$D37+1)*$J37-1),2,1),0) -> 0 | N37: =IF(AND($D37<=N$9+6,$E37>=N$9),IF(AND(ISNUMBER($J37),N$9<=$D37+($E37-$D37+1)*$J37-1),2,1),0) -> 0 | O37: =IF(AND($D37<=O$9+6,$E37>=O$9),IF(AND(ISNUMBER($J37),O$9<=$D37+($E37-$D37+1)*$J37-1),2,1),0) -> 0 | P37: =IF(AND($D37<=P$9+6,$E37>=P$9),IF(AND(ISNUMBER($J37),P$9<=$D37+($E37-$D37+1)*$J37-1),2,1),0) -> 0 | Q37: =IF(AND($D37<=Q$9+6,$E37>=Q$9),IF(AND(ISNUMBER($J37),Q$9<=$D37+($E37-$D37+1)*$J37-1),2,1),0) -> 0 | R37: =IF(AND($D37<=R$9+6,$E37>=R$9),IF(AND(ISNUMBER($J37),R$9<=$D37+($E37-$D37+1)*$J37-1),2,1),0) -> 2 | S37: =IF(AND($D37<=S$9+6,$E37>=S$9),IF(AND(ISNUMBER($J37),S$9<=$D37+($E37-$D37+1)*$J37-1),2,1),0) -> 2 | T37: =IF(AND($D37<=T$9+6,$E37>=T$9),IF(AND(ISNUMBER($J37),T$9<=$D37+($E37-$D37+1)*$J37-1),2,1),0) -> 0 | ... AB37: =IF(AND($D37<=AB$9+6,$E37>=AB$9),IF(AND(ISNUMBER($J37),AB$9<=$D37+($E37-$D37+1)*$J37-1),2,1),0) -> 0
A38: SCRUM-76 | B38: Configurar Firebase Storage | C38: Daniela | D38: =IF('Datos Jira'!G78="",'Datos Jira'!J78,'Datos Jira'!G78) -> 46301 | E38: =IF('Datos Jira'!H78="",'Datos Jira'!K78,'Datos Jira'!H78) -> 46308 | F38: Jira | G38: ='Datos Jira'!E78 -> Finalizado | H38: =COUNTIFS('Datos Jira'!$B$8:$B$234,A38) -> 7 | I38: =COUNTIFS('Datos Jira'!$B$8:$B$234,A38,'Datos Jira'!$E$8:$E$234,"Finalizado") -> 7 | J38: =IF(G38="Finalizado",1,IF(H38>0,I38/H38,IF(G38="Pendiente",0,""))) -> 1 | K38: =E38-D38+1 -> 8 | M38: =IF(AND($D38<=M$9+6,$E38>=M$9),IF(AND(ISNUMBER($J38),M$9<=$D38+($E38-$D38+1)*$J38-1),2,1),0) -> 0 | N38: =IF(AND($D38<=N$9+6,$E38>=N$9),IF(AND(ISNUMBER($J38),N$9<=$D38+($E38-$D38+1)*$J38-1),2,1),0) -> 0 | O38: =IF(AND($D38<=O$9+6,$E38>=O$9),IF(AND(ISNUMBER($J38),O$9<=$D38+($E38-$D38+1)*$J38-1),2,1),0) -> 0 | P38: =IF(AND($D38<=P$9+6,$E38>=P$9),IF(AND(ISNUMBER($J38),P$9<=$D38+($E38-$D38+1)*$J38-1),2,1),0) -> 0 | Q38: =IF(AND($D38<=Q$9+6,$E38>=Q$9),IF(AND(ISNUMBER($J38),Q$9<=$D38+($E38-$D38+1)*$J38-1),2,1),0) -> 0 | R38: =IF(AND($D38<=R$9+6,$E38>=R$9),IF(AND(ISNUMBER($J38),R$9<=$D38+($E38-$D38+1)*$J38-1),2,1),0) -> 2 | S38: =IF(AND($D38<=S$9+6,$E38>=S$9),IF(AND(ISNUMBER($J38),S$9<=$D38+($E38-$D38+1)*$J38-1),2,1),0) -> 2 | T38: =IF(AND($D38<=T$9+6,$E38>=T$9),IF(AND(ISNUMBER($J38),T$9<=$D38+($E38-$D38+1)*$J38-1),2,1),0) -> 0 | ... AB38: =IF(AND($D38<=AB$9+6,$E38>=AB$9),IF(AND(ISNUMBER($J38),AB$9<=$D38+($E38-$D38+1)*$J38-1),2,1),0) -> 0
A39: SCRUM-201 | B39: Documentación para Fase 2 | C39: Daniela | D39: =IF('Datos Jira'!G196="",'Datos Jira'!J196,'Datos Jira'!G196) -> 46302 | E39: =IF('Datos Jira'!H196="",'Datos Jira'!K196,'Datos Jira'!H196) -> 46319 | F39: Jira | G39: ='Datos Jira'!E196 -> En curso | H39: 1 | I39: 1 | J39: =IF(G39="Finalizado",1,IF(H39>0,I39/H39,IF(G39="Pendiente",0,""))) -> 1 | K39: =E39-D39+1 -> 18 | M39: =IF(AND($D39<=M$9+6,$E39>=M$9),IF(AND(ISNUMBER($J39),M$9<=$D39+($E39-$D39+1)*$J39-1),2,1),0) -> 0 | N39: =IF(AND($D39<=N$9+6,$E39>=N$9),IF(AND(ISNUMBER($J39),N$9<=$D39+($E39-$D39+1)*$J39-1),2,1),0) -> 0 | O39: =IF(AND($D39<=O$9+6,$E39>=O$9),IF(AND(ISNUMBER($J39),O$9<=$D39+($E39-$D39+1)*$J39-1),2,1),0) -> 0 | P39: =IF(AND($D39<=P$9+6,$E39>=P$9),IF(AND(ISNUMBER($J39),P$9<=$D39+($E39-$D39+1)*$J39-1),2,1),0) -> 0 | Q39: =IF(AND($D39<=Q$9+6,$E39>=Q$9),IF(AND(ISNUMBER($J39),Q$9<=$D39+($E39-$D39+1)*$J39-1),2,1),0) -> 0 | R39: =IF(AND($D39<=R$9+6,$E39>=R$9),IF(AND(ISNUMBER($J39),R$9<=$D39+($E39-$D39+1)*$J39-1),2,1),0) -> 2 | S39: =IF(AND($D39<=S$9+6,$E39>=S$9),IF(AND(ISNUMBER($J39),S$9<=$D39+($E39-$D39+1)*$J39-1),2,1),0) -> 2 | T39: =IF(AND($D39<=T$9+6,$E39>=T$9),IF(AND(ISNUMBER($J39),T$9<=$D39+($E39-$D39+1)*$J39-1),2,1),0) -> 2 | ... AB39: =IF(AND($D39<=AB$9+6,$E39>=AB$9),IF(AND(ISNUMBER($J39),AB$9<=$D39+($E39-$D39+1)*$J39-1),2,1),0) -> 0
A40: SCRUM-216 | B40: Eliminar el modo "Solo jugar" y adaptar la app a 2 modos de uso | C40: Benjamín | D40: =IF('Datos Jira'!G211="",'Datos Jira'!J211,'Datos Jira'!G211) -> 46296 | E40: =IF('Datos Jira'!H211="",'Datos Jira'!K211,'Datos Jira'!H211) -> 46308 | F40: Mixto | G40: ='Datos Jira'!E211 -> Finalizado | H40: =COUNTIFS('Datos Jira'!$B$8:$B$234,A40) -> 7 | I40: =COUNTIFS('Datos Jira'!$B$8:$B$234,A40,'Datos Jira'!$E$8:$E$234,"Finalizado") -> 7 | J40: =IF(G40="Finalizado",1,IF(H40>0,I40/H40,IF(G40="Pendiente",0,""))) -> 1 | K40: =E40-D40+1 -> 13 | M40: =IF(AND($D40<=M$9+6,$E40>=M$9),IF(AND(ISNUMBER($J40),M$9<=$D40+($E40-$D40+1)*$J40-1),2,1),0) -> 0 | N40: =IF(AND($D40<=N$9+6,$E40>=N$9),IF(AND(ISNUMBER($J40),N$9<=$D40+($E40-$D40+1)*$J40-1),2,1),0) -> 0 | O40: =IF(AND($D40<=O$9+6,$E40>=O$9),IF(AND(ISNUMBER($J40),O$9<=$D40+($E40-$D40+1)*$J40-1),2,1),0) -> 0 | P40: =IF(AND($D40<=P$9+6,$E40>=P$9),IF(AND(ISNUMBER($J40),P$9<=$D40+($E40-$D40+1)*$J40-1),2,1),0) -> 0 | Q40: =IF(AND($D40<=Q$9+6,$E40>=Q$9),IF(AND(ISNUMBER($J40),Q$9<=$D40+($E40-$D40+1)*$J40-1),2,1),0) -> 2 | R40: =IF(AND($D40<=R$9+6,$E40>=R$9),IF(AND(ISNUMBER($J40),R$9<=$D40+($E40-$D40+1)*$J40-1),2,1),0) -> 2 | S40: =IF(AND($D40<=S$9+6,$E40>=S$9),IF(AND(ISNUMBER($J40),S$9<=$D40+($E40-$D40+1)*$J40-1),2,1),0) -> 2 | T40: =IF(AND($D40<=T$9+6,$E40>=T$9),IF(AND(ISNUMBER($J40),T$9<=$D40+($E40-$D40+1)*$J40-1),2,1),0) -> 0 | ... AB40: =IF(AND($D40<=AB$9+6,$E40>=AB$9),IF(AND(ISNUMBER($J40),AB$9<=$D40+($E40-$D40+1)*$J40-1),2,1),0) -> 0
A41: SCRUM-217 | B41: Indicar con claridad dónde está el error al crear cuenta e iniciar sesión | C41: Benjamín | D41: =IF('Datos Jira'!G212="",'Datos Jira'!J212,'Datos Jira'!G212) -> 46296 | E41: =IF('Datos Jira'!H212="",'Datos Jira'!K212,'Datos Jira'!H212) -> 46308 | F41: Mixto | G41: ='Datos Jira'!E212 -> Finalizado | H41: =COUNTIFS('Datos Jira'!$B$8:$B$234,A41) -> 6 | I41: =COUNTIFS('Datos Jira'!$B$8:$B$234,A41,'Datos Jira'!$E$8:$E$234,"Finalizado") -> 6 | J41: =IF(G41="Finalizado",1,IF(H41>0,I41/H41,IF(G41="Pendiente",0,""))) -> 1 | K41: =E41-D41+1 -> 13 | M41: =IF(AND($D41<=M$9+6,$E41>=M$9),IF(AND(ISNUMBER($J41),M$9<=$D41+($E41-$D41+1)*$J41-1),2,1),0) -> 0 | N41: =IF(AND($D41<=N$9+6,$E41>=N$9),IF(AND(ISNUMBER($J41),N$9<=$D41+($E41-$D41+1)*$J41-1),2,1),0) -> 0 | O41: =IF(AND($D41<=O$9+6,$E41>=O$9),IF(AND(ISNUMBER($J41),O$9<=$D41+($E41-$D41+1)*$J41-1),2,1),0) -> 0 | P41: =IF(AND($D41<=P$9+6,$E41>=P$9),IF(AND(ISNUMBER($J41),P$9<=$D41+($E41-$D41+1)*$J41-1),2,1),0) -> 0 | Q41: =IF(AND($D41<=Q$9+6,$E41>=Q$9),IF(AND(ISNUMBER($J41),Q$9<=$D41+($E41-$D41+1)*$J41-1),2,1),0) -> 2 | R41: =IF(AND($D41<=R$9+6,$E41>=R$9),IF(AND(ISNUMBER($J41),R$9<=$D41+($E41-$D41+1)*$J41-1),2,1),0) -> 2 | S41: =IF(AND($D41<=S$9+6,$E41>=S$9),IF(AND(ISNUMBER($J41),S$9<=$D41+($E41-$D41+1)*$J41-1),2,1),0) -> 2 | T41: =IF(AND($D41<=T$9+6,$E41>=T$9),IF(AND(ISNUMBER($J41),T$9<=$D41+($E41-$D41+1)*$J41-1),2,1),0) -> 0 | ... AB41: =IF(AND($D41<=AB$9+6,$E41>=AB$9),IF(AND(ISNUMBER($J41),AB$9<=$D41+($E41-$D41+1)*$J41-1),2,1),0) -> 0
A42: SCRUM-218 | B42: Mantener la sesión iniciada al volver a abrir la app | C42: Benjamín | D42: =IF('Datos Jira'!G213="",'Datos Jira'!J213,'Datos Jira'!G213) -> 46296 | E42: =IF('Datos Jira'!H213="",'Datos Jira'!K213,'Datos Jira'!H213) -> 46308 | F42: Mixto | G42: ='Datos Jira'!E213 -> Finalizado | H42: =COUNTIFS('Datos Jira'!$B$8:$B$234,A42) -> 8 | I42: =COUNTIFS('Datos Jira'!$B$8:$B$234,A42,'Datos Jira'!$E$8:$E$234,"Finalizado") -> 8 | J42: =IF(G42="Finalizado",1,IF(H42>0,I42/H42,IF(G42="Pendiente",0,""))) -> 1 | K42: =E42-D42+1 -> 13 | M42: =IF(AND($D42<=M$9+6,$E42>=M$9),IF(AND(ISNUMBER($J42),M$9<=$D42+($E42-$D42+1)*$J42-1),2,1),0) -> 0 | N42: =IF(AND($D42<=N$9+6,$E42>=N$9),IF(AND(ISNUMBER($J42),N$9<=$D42+($E42-$D42+1)*$J42-1),2,1),0) -> 0 | O42: =IF(AND($D42<=O$9+6,$E42>=O$9),IF(AND(ISNUMBER($J42),O$9<=$D42+($E42-$D42+1)*$J42-1),2,1),0) -> 0 | P42: =IF(AND($D42<=P$9+6,$E42>=P$9),IF(AND(ISNUMBER($J42),P$9<=$D42+($E42-$D42+1)*$J42-1),2,1),0) -> 0 | Q42: =IF(AND($D42<=Q$9+6,$E42>=Q$9),IF(AND(ISNUMBER($J42),Q$9<=$D42+($E42-$D42+1)*$J42-1),2,1),0) -> 2 | R42: =IF(AND($D42<=R$9+6,$E42>=R$9),IF(AND(ISNUMBER($J42),R$9<=$D42+($E42-$D42+1)*$J42-1),2,1),0) -> 2 | S42: =IF(AND($D42<=S$9+6,$E42>=S$9),IF(AND(ISNUMBER($J42),S$9<=$D42+($E42-$D42+1)*$J42-1),2,1),0) -> 2 | T42: =IF(AND($D42<=T$9+6,$E42>=T$9),IF(AND(ISNUMBER($J42),T$9<=$D42+($E42-$D42+1)*$J42-1),2,1),0) -> 0 | ... AB42: =IF(AND($D42<=AB$9+6,$E42>=AB$9),IF(AND(ISNUMBER($J42),AB$9<=$D42+($E42-$D42+1)*$J42-1),2,1),0) -> 0
B43: Módulo cuidador y QR
A44: SCRUM-29 | B44: Primera sesión de prueba con usuarios | C44: Daniela | D44: =IF('Datos Jira'!G31="",'Datos Jira'!J31,'Datos Jira'!G31) -> 46321 | E44: =IF('Datos Jira'!H31="",'Datos Jira'!K31,'Datos Jira'!H31) -> 46341 | F44: Sprint | G44: ='Datos Jira'!E31 -> Pendiente | H44: =COUNTIFS('Datos Jira'!$B$8:$B$234,A44) -> 6 | I44: =COUNTIFS('Datos Jira'!$B$8:$B$234,A44,'Datos Jira'!$E$8:$E$234,"Finalizado") -> 0 | J44: =IF(G44="Finalizado",1,IF(H44>0,I44/H44,IF(G44="Pendiente",0,""))) -> 0 | K44: =E44-D44+1 -> 21 | M44: =IF(AND($D44<=M$9+6,$E44>=M$9),IF(AND(ISNUMBER($J44),M$9<=$D44+($E44-$D44+1)*$J44-1),2,1),0) -> 0 | N44: =IF(AND($D44<=N$9+6,$E44>=N$9),IF(AND(ISNUMBER($J44),N$9<=$D44+($E44-$D44+1)*$J44-1),2,1),0) -> 0 | O44: =IF(AND($D44<=O$9+6,$E44>=O$9),IF(AND(ISNUMBER($J44),O$9<=$D44+($E44-$D44+1)*$J44-1),2,1),0) -> 0 | P44: =IF(AND($D44<=P$9+6,$E44>=P$9),IF(AND(ISNUMBER($J44),P$9<=$D44+($E44-$D44+1)*$J44-1),2,1),0) -> 0 | Q44: =IF(AND($D44<=Q$9+6,$E44>=Q$9),IF(AND(ISNUMBER($J44),Q$9<=$D44+($E44-$D44+1)*$J44-1),2,1),0) -> 0 | R44: =IF(AND($D44<=R$9+6,$E44>=R$9),IF(AND(ISNUMBER($J44),R$9<=$D44+($E44-$D44+1)*$J44-1),2,1),0) -> 0 | S44: =IF(AND($D44<=S$9+6,$E44>=S$9),IF(AND(ISNUMBER($J44),S$9<=$D44+($E44-$D44+1)*$J44-1),2,1),0) -> 0 | T44: =IF(AND($D44<=T$9+6,$E44>=T$9),IF(AND(ISNUMBER($J44),T$9<=$D44+($E44-$D44+1)*$J44-1),2,1),0) -> 0 | ... AB44: =IF(AND($D44<=AB$9+6,$E44>=AB$9),IF(AND(ISNUMBER($J44),AB$9<=$D44+($E44-$D44+1)*$J44-1),2,1),0) -> 0
...

Sheet Datos Jira
A2: Datos originales y correspondencia con GitHub
A3: Tareas principales: consulta Jira 23/10/2026. Subtareas: copia inicial del mismo día.
A4: Jira: https://duocuc-team-auroracare.atlassian.net/issues/?jql=project%3DSCRUM
A5: GitHub: https://github.com/users/Franky1764/projects/1.
A6: Propuesta de cierre: 07-20/12/2026, según período de entrega del README del Project.
A7: Clave | B7: Padre Jira | C7: Actividad | D7: Tipo | E7: Estado | F7: Responsable | G7: Inicio Jira | H7: Término Jira | I7: Sprint | J7: Inicio sprint | K7: Fin sprint | L7: Issue GitHub | M7: Enlace Jira
A8: SCRUM-5 | C8: Instalar stack en los equipos de desarrollo | D8: Tarea | E8: Finalizado | F8: Daniela | G8: 46265 | H8: 46270 | I8: Sprint 1 - Fundamentos | J8: 46265 | K8: 46278 | L8: 2 | M8: https://duocuc-team-auroracare.atlassian.net/browse/SCRUM-5
A9: SCRUM-6 | C9: Configurar repositorio GitHub | D9: Tarea | E9: Finalizado | F9: Daniela | H9: 46278 | I9: Sprint 1 - Fundamentos | J9: 46265 | K9: 46278 | L9: 3 | M9: https://duocuc-team-auroracare.atlassian.net/browse/SCRUM-6
A10: SCRUM-7 | C10: Crear proyecto Firebase | D10: Tarea | E10: Finalizado | F10: Daniela | H10: 46278 | I10: Sprint 1 - Fundamentos | J10: 46265 | K10: 46278 | L10: 4 | M10: https://duocuc-team-auroracare.atlassian.net/browse/SCRUM-7
A11: SCRUM-8 | C11: Spike técnico Flutter -> FastAPI -> OpenAI | D11: Tarea | E11: Finalizado | F11: Daniela | G11: 46267 | H11: 46278 | I11: Sprint 1 - Fundamentos | J11: 46265 | K11: 46278 | L11: 5 | M11: https://duocuc-team-auroracare.atlassian.net/browse/SCRUM-8
A12: SCRUM-9 | C12: Configurar Jira | D12: Tarea | E12: Finalizado | F12: Daniela | H12: 46270 | I12: Sprint 1 - Fundamentos | J12: 46265 | K12: 46278 | L12: 6 | M12: https://duocuc-team-auroracare.atlassian.net/browse/SCRUM-9
A13: SCRUM-10 | C13: Reunión de kickoff del equipo | D13: Tarea | E13: Finalizado | F13: Daniela | H13: 46275 | I13: Sprint 1 - Fundamentos | J13: 46265 | K13: 46278 | L13: 7 | M13: https://duocuc-team-auroracare.atlassian.net/browse/SCRUM-10
A14: SCRUM-11 | B14: SCRUM-5 | C14: Instalación – Daniela | D14: Subtask | E14: Finalizado | F14: Daniela | I14: Sprint 1 - Fundamentos | J14: 46265 | K14: 46278 | L14: 87 | M14: https://duocuc-team-auroracare.atlassian.net/browse/SCRUM-11
A15: SCRUM-12 | B15: SCRUM-5 | C15: Instalación – Eduardo | D15: Subtask | E15: Finalizado | F15: Eduardo | I15: Sprint 1 - Fundamentos | J15: 46265 | K15: 46278 | L15: 88 | M15: https://duocuc-team-auroracare.atlassian.net/browse/SCRUM-12
A16: SCRUM-13 | B16: SCRUM-5 | C16: Instalación – Benjamín | D16: Subtask | E16: Finalizado | F16: Benjamín | I16: Sprint 1 - Fundamentos | J16: 46265 | K16: 46278 | L16: 89 | M16: https://duocuc-team-auroracare.atlassian.net/browse/SCRUM-13
A17: SCRUM-14 | C17: Estructura de capas Flutter | D17: Tarea | E17: Finalizado | F17: Daniela | H17: 46287 | I17: Sprint 2 – Arquitectura y Auth | J17: 46273 | K17: 46301 | L17: 8 | M17: https://duocuc-team-auroracare.atlassian.net/browse/SCRUM-14
A18: SCRUM-15 | C18: Tema visual AuroraCare | D18: Tarea | E18: Finalizado | F18: Benjamín | H18: 46287 | I18: Sprint 2 – Arquitectura y Auth | J18: 46273 | K18: 46301 | L18: 9 | M18: https://duocuc-team-auroracare.atlassian.net/browse/SCRUM-15
A19: SCRUM-16 | C19: Pantalla de Bienvenida y Login | D19: Tarea | E19: Finalizado | F19: Benjamín | H19: 46291 | I19: Sprint 2 – Arquitectura y Auth | J19: 46273 | K19: 46301 | L19: 27 | M19: https://duocuc-team-auroracare.atlassian.net/browse/SCRUM-16
A20: SCRUM-17 | C20: Disclaimer médico en onboarding | D20: Tarea | E20: Finalizado | F20: Benjamín | H20: 46291 | I20: Sprint 2 – Arquitectura y Auth | J20: 46273 | K20: 46301 | L20: 28 | M20: https://duocuc-team-auroracare.atlassian.net/browse/SCRUM-17
A21: SCRUM-18 | C21: Selección de modo de uso | D21: Tarea | E21: Finalizado | F21: Benjamín | H21: 46295 | I21: Sprint 2 – Arquitectura y Auth | J21: 46273 | K21: 46301 | L21: 29 | M21: https://duocuc-team-auroracare.atlassian.net/browse/SCRUM-18
A22: SCRUM-19 | C22: Generación UUID anónimo | D22: Tarea | E22: Finalizado | F22: Daniela | H22: 46293 | I22: Sprint 2 – Arquitectura y Auth | J22: 46273 | K22: 46301 | L22: 31 | M22: https://duocuc-team-auroracare.atlassian.net/browse/SCRUM-19
A23: SCRUM-20 | C23: Prototipo Figma – Flujos Completos 9 - 12 | D23: Tarea | E23: Finalizado | F23: Daniela | H23: 46299 | I23: Sprint 2 – Arquitectura y Auth | J23: 46273 | K23: 46301 | L23: 90 | M23: https://duocuc-team-auroracare.atlassian.net/browse/SCRUM-20
A24: SCRUM-21 | C24: Juegos (Memoria) | D24: Tarea | E24: En curso | F24: Benjamín | G24: 46307 | H24: 46318 | I24: Sprint 3 – Juegos y Métricas | J24: 46296 | K24: 46320 | L24: 91 | M24: https://duocuc-team-auroracare.atlassian.net/browse/SCRUM-21
A25: SCRUM-22 | C25: Juegos (Praxias) | D25: Tarea | E25: Finalizado | F25: Daniela | G25: 46307 | H25: 46318 | I25: Sprint 3 – Juegos y Métricas | J25: 46296 | K25: 46320 | L25: 92 | M25: https://duocuc-team-auroracare.atlassian.net/browse/SCRUM-22
A26: SCRUM-23 | C26: Juegos (Atención) | D26: Tarea | E26: En curso | F26: Eduardo | G26: 46307 | H26: 46318 | I26: Sprint 3 – Juegos y Métricas | J26: 46296 | K26: 46320 | L26: 93 | M26: https://duocuc-team-auroracare.atlassian.net/browse/SCRUM-23
A27: SCRUM-24 | C27: Módulo de respiración guiada | D27: Tarea | E27: Finalizado | F27: Benjamín | G27: 46307 | H27: 46318 | I27: Sprint 3 – Juegos y Métricas | J27: 46296 | K27: 46320 | L27: 94 | M27: https://duocuc-team-auroracare.atlassian.net/browse/SCRUM-24
A28: SCRUM-25 | C28: Captura de métricas por sesión | D28: Tarea | E28: Finalizado | F28: Daniela | G28: 46300 | H28: 46308 | I28: Sprint 3 – Juegos y Métricas | J28: 46296 | K28: 46320 | L28: 83 | M28: https://duocuc-team-auroracare.atlassian.net/browse/SCRUM-25
A29: SCRUM-26 | C29: Pruebas QA | D29: Tarea | E29: Pendiente | F29: Eduardo | G29: 46318 | H29: 46320 | I29: Sprint 3 – Juegos y Métricas | J29: 46296 | K29: 46320 | L29: 32 | M29: https://duocuc-team-auroracare.atlassian.net/browse/SCRUM-26
A30: SCRUM-28 | C30: FastAPI - endpoint/session/analyze | D30: Tarea | E30: Finalizado | F30: Daniela | G30: 46302 | H30: 46308 | I30: Sprint 3 – Juegos y Métricas | J30: 46296 | K30: 46320 | L30: 95 | M30: https://duocuc-team-auroracare.atlassian.net/browse/SCRUM-28
A31: SCRUM-29 | C31: Primera sesión de prueba con usuarios | D31: Tarea | E31: Pendiente | F31: Daniela | I31: Sprint 4 – Módulo Cuidador QR | J31: 46321 | K31: 46341 | L31: 96 | M31: https://duocuc-team-auroracare.atlassian.net/browse/SCRUM-29
A32: SCRUM-30 | C32: Generación de QR por adulto mayor | D32: Tarea | E32: Pendiente | F32: Daniela | I32: Sprint 4 – Módulo Cuidador QR | J32: 46321 | K32: 46341 | L32: 97 | M32: https://duocuc-team-auroracare.atlassian.net/browse/SCRUM-30
A33: SCRUM-31 | C33: Escaneo de QR por cuidador | D33: Tarea | E33: Pendiente | F33: Eduardo | I33: Sprint 4 – Módulo Cuidador QR | J33: 46321 | K33: 46341 | L33: 98 | M33: https://duocuc-team-auroracare.atlassian.net/browse/SCRUM-31
A34: SCRUM-32 | C34: Dashboard cuidador | D34: Tarea | E34: Pendiente | F34: Eduardo | I34: Sprint 4 – Módulo Cuidador QR | J34: 46321 | K34: 46341 | L34: 99 | M34: https://duocuc-team-auroracare.atlassian.net/browse/SCRUM-32
A35: SCRUM-33 | C35: Historial de resultados | D35: Tarea | E35: Pendiente | F35: Eduardo | I35: Sprint 4 – Módulo Cuidador QR | J35: 46321 | K35: 46341 | L35: 100 | M35: https://duocuc-team-auroracare.atlassian.net/browse/SCRUM-33
A36: SCRUM-34 | C36: Notificación push al cuidador | D36: Tarea | E36: Pendiente | F36: Eduardo | I36: Sprint 4 – Módulo Cuidador QR | J36: 46321 | K36: 46341 | L36: 101 | M36: https://duocuc-team-auroracare.atlassian.net/browse/SCRUM-34
A37: SCRUM-35 | C37: Vista de progreso personal | D37: Tarea | E37: Pendiente | F37: Benjamín | I37: Sprint 4 – Módulo Cuidador QR | J37: 46321 | K37: 46341 | L37: 102 | M37: https://duocuc-team-auroracare.atlassian.net/browse/SCRUM-35
A38: SCRUM-36 | C38: FastAPI – endpoint/report/generate | D38: Tarea | E38: Pendiente | F38: Daniela | I38: Sprint 4 – Módulo Cuidador QR | J38: 46321 | K38: 46341 | L38: 103 | M38: https://duocuc-team-auroracare.atlassian.net/browse/SCRUM-36
A39: SCRUM-37 | C39: Pruebas QA | D39: Tarea | E39: Pendiente | F39: Eduardo | I39: Sprint 4 – Módulo Cuidador QR | J39: 46321 | K39: 46341 | L39: 104 | M39: https://duocuc-team-auroracare.atlassian.net/browse/SCRUM-37
A40: SCRUM-38 | C40: Segunda sesión de pruebas con usuarios | D40: Tarea | E40: Pendiente | F40: Daniela | I40: Sprint 4 – Módulo Cuidador QR | J40: 46321 | K40: 46341 | L40: 105 | M40: https://duocuc-team-auroracare.atlassian.net/browse/SCRUM-38
A41: SCRUM-39 | C41: flujo ARCO completo | D41: Tarea | E41: Pendiente | F41: Daniela | I41: Sprint 5 – Privacidad/ Reporte | J41: 46342 | K41: 46362 | L41: 106 | M41: https://duocuc-team-auroracare.atlassian.net/browse/SCRUM-39
...
